#VRML_SIM R2023b utf8
# license: Apache License 2.0
# license url: http://www.apache.org/licenses/LICENSE-2.0
# This is a proto file for Webots for the nugus
# Extracted from: /home/tom/NUbots/NUWebots/protos/robot/nugus/robot.urdf

PROTO nugus [
field  SFVec3f     translation          0 0 0
  field  SFRotation  rotation             0 1 0 0
  field  SFString    name                 "nugus"            # Is `Robot.name`.
  # Find in "webots/projects/samples/contests/robocup/controllers/player"
  field  SFString    controller           "nugus_controller"
  # Is `Robot.controllerArgs`.
  field  MFString    controllerArgs       []
  # Is `Robot.customData`.
  field  SFString    customData           ""
  # Is `Robot.supervisor`.
  field  SFBool      supervisor           FALSE
  # Is `Robot.synchronization`.
  field  SFBool      synchronization      TRUE
  # Is `Robot.selfCollision`.
  field  SFBool      selfCollision        TRUE
  # MOTOR PARAMETER: See section 2. of docs/Robot_Model_RoboCup_2021 for more information
  field  SFFloat     MX106-torque         10.00
  field  SFFloat     MX106-vel            5.76
  field  SFFloat     MX106-damping        1.23
  field  SFFloat     MX106-friction       2.55
  field  SFFloat     DYNAMIXEL-RESOLUTION 0.0015
  # CAMERA PARAMETERS: See docs for more information
  # Approximates PI/2 radians (90 degrees)
  field SFFloat      fieldOfView            1.5707
  field SFInt32      cameraWidth            640              # 640 pixels
  field SFInt32      cameraHeight           480              # 480 pixels
  # 1.98mm, as from our real cameras (https://www.lensation.de/pdf/BF10M19828S118C.pdf)
  field SFFloat      cameraLensFocalLength  1.98
  # Not much noise on real cameras
  field SFFloat      cameraNoise            0.000000001
  # With over 100fps, real cameras do not have much motion blur
  field SFFloat      cameraMotionBlur       10
  field MFColor      recognitionColors      [0 0 1]
  # Used in the vision data collection tool
  field SFFloat      height                 0.51

]
{
  Robot {
    translation IS translation
    rotation IS rotation
    controller IS controller
    controllerArgs IS controllerArgs
    customData IS customData
    supervisor IS supervisor
    synchronization IS synchronization
    selfCollision IS selfCollision
    children [
                            Transform {
                                # Accelerometer and Gyro are positioned 0.2m above torso base
                                translation 0.000000 0.000000 0.2
                                children [
                                #(See Section 1. of docs/Robot_Model_RoboCup_2021 for details on noise)
                                # Axis: x forward, y left, z up
                                # Units are [m/s^2]
                                # The acelerometer measures the reaction forces over 3 axes in [m/s^2], thus,
                                # at rest the accelerometer should read +9.81 [m/s^2] in the z axis.
                                # Range is -39.24 to 39.24 [m/s^2]
                                # Return value (2nd column of LUT) is offset by 100
                                Accelerometer {
                                    name "accelerometer"
                                    xAxis TRUE
                                    yAxis TRUE
                                    zAxis TRUE
                                    # Calculation used: (size of range)/4095
                                    resolution 0.01916
                                    lookupTable [
                                    -39.24 60.76 0.000704
                                    39.24  139.24 0.000307
                                    ]
                                }
                                # 'L3G4200D' Gyro
                                # (See Section 1. of docs/Robot_Model_RoboCup_2021 for details on noise)
                                # Axis: x forward, y left, z up
                                # Units are [rad/s]
                                # Range is -8.72665 to 8.72665 [rad/s]
                                # Return value (2nd column of LUT) is offset by 100
                                Gyro {
                                    name "gyroscope"
                                    xAxis TRUE
                                    yAxis TRUE
                                    zAxis TRUE
                                    # Calculation used: (size of range)/4095
                                    resolution 0.0042621
                                    lookupTable [
                                    -8.72665 91.238   0.0001151
                                    8.72665  108.762  0.000096541
                                    ]
                                }
                                ]
                            }
                        
      Shape {
        appearance DEF torso_material PBRAppearance {
          baseColor 0.286275 0.286275 0.286275
          roughness 1.000000
          metalness 0
        }
        geometry DEF torso_visual Mesh {
          url "torso_visual.stl"
        }
      }
      HingeJoint {
        jointParameters HingeJointParameters {
                    dampingConstant IS MX106-damping
                    staticFriction IS MX106-friction
          axis 0.000000 0.000000 1.000000
          anchor 0.000000 0.055000 0.000000
        }
        device [
          RotationalMotor {
            name "left_hip_yaw"
            maxVelocity IS MX106-vel
            minPosition -3.14159
            maxPosition 3.14159
            maxTorque IS MX106-torque
          }
          PositionSensor {
                 resolution IS DYNAMIXEL-RESOLUTION
            name "left_hip_yaw_sensor"
          }
        ]
        endPoint Solid {
          translation 0.000000 0.055000 0.000000
          children [
            Shape {
              appearance DEF left_hip_yaw_material PBRAppearance {
                baseColor 0.286275 0.286275 0.286275
                roughness 1.000000
                metalness 0
              }
              geometry DEF left_hip_yaw_visual Mesh {
                url "left_hip_yaw_visual.stl"
              }
            }
            HingeJoint {
              jointParameters HingeJointParameters {
                    dampingConstant IS MX106-damping
                    staticFriction IS MX106-friction
                axis 1.000000 0.000000 -0.000004
                anchor 0.022133 0.000000 -0.054500
              }
              device [
                RotationalMotor {
                  name "left_hip_roll"
                  maxVelocity IS MX106-vel
                  minPosition -3.14159
                  maxPosition 3.14159
                  maxTorque IS MX106-torque
                }
                PositionSensor {
                 resolution IS DYNAMIXEL-RESOLUTION
                  name "left_hip_roll_sensor"
                }
              ]
              endPoint Solid {
                translation 0.022133 0.000000 -0.054500
                rotation -0.000000 1.000000 0.000000 1.570800
                children [
                  Shape {
                    appearance DEF left_hip_roll_material PBRAppearance {
                      baseColor 0.286275 0.286275 0.286275
                      roughness 1.000000
                      metalness 0
                    }
                    geometry DEF left_hip_roll_visual Mesh {
                      url "left_hip_roll_visual.stl"
                    }
                  }
                  HingeJoint {
                    jointParameters HingeJointParameters {
                    dampingConstant IS MX106-damping
                    staticFriction IS MX106-friction
                      axis -0.000000 1.000000 -0.000004
                      anchor 0.000000 -0.000000 -0.000000
                    }
                    device [
                      RotationalMotor {
                        name "left_hip_pitch"
                        maxVelocity IS MX106-vel
                        minPosition -3.14159
                        maxPosition 3.14159
                        maxTorque IS MX106-torque
                      }
                      PositionSensor {
                 resolution IS DYNAMIXEL-RESOLUTION
                        name "left_hip_pitch_sensor"
                      }
                    ]
                    endPoint Solid {
                      translation 0.000000 -0.000000 -0.000000
                      rotation -1.000000 -0.000000 0.000000 1.570800
                      children [
                        Shape {
                          appearance DEF left_upper_leg_material PBRAppearance {
                            baseColor 0.701961 0.701961 0.701961
                            roughness 1.000000
                            metalness 0
                          }
                          geometry DEF left_upper_leg_visual Mesh {
                            url "left_upper_leg_visual.stl"
                          }
                        }
                        HingeJoint {
                          jointParameters HingeJointParameters {
                    dampingConstant IS MX106-damping
                    staticFriction IS MX106-friction
                            axis 0.000000 0.000000 1.000000
                            anchor 0.206046 0.056950 -0.000000
                          }
                          device [
                            RotationalMotor {
                              name "left_knee"
                              maxVelocity IS MX106-vel
                              minPosition -3.14159
                              maxPosition 3.14159
                              maxTorque IS MX106-torque
                            }
                            PositionSensor {
                 resolution IS DYNAMIXEL-RESOLUTION
                              name "left_knee_sensor"
                            }
                          ]
                          endPoint Solid {
                            translation 0.206046 0.056950 -0.000000
                            children [
                              Shape {
                                appearance DEF left_lower_leg_material PBRAppearance {
                                  baseColor 0.737255 0.721569 0.717647
                                  roughness 1.000000
                                  metalness 0
                                }
                                geometry DEF left_lower_leg_visual Mesh {
                                  url "left_lower_leg_visual.stl"
                                }
                              }
                              HingeJoint {
                                jointParameters HingeJointParameters {
                    dampingConstant IS MX106-damping
                    staticFriction IS MX106-friction
                                  axis 0.000000 0.000000 1.000000
                                  anchor 0.200203 -0.000000 0.000000
                                }
                                device [
                                  RotationalMotor {
                                    name "left_ankle_pitch"
                                    maxVelocity IS MX106-vel
                                    minPosition -3.14159
                                    maxPosition 3.14159
                                    maxTorque IS MX106-torque
                                  }
                                  PositionSensor {
                 resolution IS DYNAMIXEL-RESOLUTION
                                    name "left_ankle_pitch_sensor"
                                  }
                                ]
                                endPoint Solid {
                                  translation 0.200203 -0.000000 0.000000
                                  children [
                                    Shape {
                                      appearance DEF left_ankle_material PBRAppearance {
                                        baseColor 0.286275 0.286275 0.286275
                                        roughness 1.000000
                                        metalness 0
                                      }
                                      geometry DEF left_ankle_visual Mesh {
                                        url "left_ankle_visual.stl"
                                      }
                                    }
                                    HingeJoint {
                                      jointParameters HingeJointParameters {
                    dampingConstant IS MX106-damping
                    staticFriction IS MX106-friction
                                        axis -0.000000 -1.000000 -0.000004
                                        anchor 0.000000 0.000000 0.000000
                                      }
                                      device [
                                        RotationalMotor {
                                          name "left_ankle_roll"
                                          maxVelocity IS MX106-vel
                                          minPosition -3.14159
                                          maxPosition 3.14159
                                          maxTorque IS MX106-torque
                                        }
                                        PositionSensor {
                 resolution IS DYNAMIXEL-RESOLUTION
                                          name "left_ankle_roll_sensor"
                                        }
                                      ]
                                      endPoint Solid {
                                        translation 0.000000 0.000000 0.000000
                                        rotation 1.000000 -0.000000 -0.000000 1.570800
                                        children [
                                          Shape {
                                            appearance DEF left_foot_material PBRAppearance {
                                              baseColor 0.286275 0.286275 0.286275
                                              roughness 1.000000
                                              metalness 0
                                            }
                                            geometry DEF left_foot_visual Mesh {
                                              url "left_foot_visual.stl"
                                            }
                                          }
                                          Solid {
                                            translation 0.036025 0.000000 0.000000
                                            rotation -0.000000 -1.000000 -0.000000 1.570800
                                            children [
                                              Shape {
                                                appearance DEF left_foot_base_material PBRAppearance {
                                                  baseColor 0.500000 0.500000 0.500000
                                                  roughness 1.000000
                                                  metalness 0
                                                }
                                                geometry DEF left_foot_base_visual Mesh {
                                                  url "left_foot_base_visual.stl"
                                                }
                                              }
                                            ]
                                            name "left_foot_base"
                                            boundingObject DEF left_foot_base_collision Mesh {
                                              url "left_foot_base_collision.stl"
                                            }
                                            physics Physics {
                                              density -1
                                              mass 0.000000
                                            }
                                          }
                                        
                                          # Define four touch sensors for the left foot
                                          # Back right touch sensor on left foot
                                          TouchSensor {
                                            translation -0.041 0.025 -0.061
                                            name "left_touch_sensor_br"
                                            type "bumper"
                                          }
                                          # Back left touch sensor on left foot
                                          TouchSensor {
                                            translation 0.057 0.025 -0.061
                                            name "left_touch_sensor_bl"
                                            type "bumper"
                                          }
                                          # Front left touch sensor on left foot
                                          TouchSensor {
                                            translation 0.057 -0.154 -0.061
                                            name "left_touch_sensor_fl"
                                            type "bumper"
                                          }
                                          # Front right touch sensor on left foot
                                          TouchSensor {
                                            translation -0.041 -0.154 -0.061
                                            name "left_touch_sensor_fr"
                                            type "bumper"
                                          }
                                        ]
                                        name "left_foot [foot]"
                                        boundingObject DEF left_foot_collision Mesh {
                                          url "left_foot_collision.stl"
                                        }
                                        physics Physics {
                                          density -1
                                          mass 0.245581
                                          centerOfMass [ 0.024823 0.007985 0.033284 ]
                                          inertiaMatrix [
                                            1.347220e-03 1.083830e-03 3.320290e-04
                                            -9.736970e-06 2.738200e-08 -1.340650e-05
                                          ]
                                        }
                                      }
                                    }
                                  ]
                                  name "left_ankle"
                                  boundingObject DEF left_ankle_collision Mesh {
                                    url "left_ankle_collision.stl"
                                  }
                                  physics Physics {
                                    density -1
                                    mass 0.329993
                                    centerOfMass [ -0.015733 0.021976 0.000513 ]
                                    inertiaMatrix [
                                      2.657620e-04 1.578470e-04 2.656770e-04
                                      1.273040e-09 1.319680e-18 3.682900e-06
                                    ]
                                  }
                                }
                              }
                            ]
                            name "left_lower_leg"
                            boundingObject DEF left_lower_leg_collision Mesh {
                              url "left_lower_leg_collision.stl"
                            }
                            physics Physics {
                              density -1
                              mass 0.089301
                              centerOfMass [ 0.100100 0.003882 -0.000000 ]
                              inertiaMatrix [
                                9.012540e-05 4.089510e-04 3.363000e-04
                                1.571840e-09 -7.871580e-11 1.161010e-11
                              ]
                            }
                          }
                        }
                      ]
                      name "left_upper_leg"
                      boundingObject DEF left_upper_leg_collision Mesh {
                        url "left_upper_leg_collision.stl"
                      }
                      physics Physics {
                        density -1
                        mass 0.136613
                        centerOfMass [ 0.079792 0.033712 -0.000001 ]
                        inertiaMatrix [
                          1.457710e-04 5.852650e-04 5.100870e-04
                          -4.011750e-05 1.280260e-08 -8.072760e-10
                        ]
                      }
                    }
                  }
                ]
                name "left_hip_roll"
                boundingObject DEF left_hip_roll_collision Mesh {
                  url "left_hip_roll_collision.stl"
                }
                physics Physics {
                  density -1
                  mass 0.395953
                  centerOfMass [ 0.015733 -0.000686 -0.021707 ]
                  inertiaMatrix [
                    3.142980e-04 3.758080e-04 1.277850e-04
                    1.527500e-09 9.783650e-18 5.620380e-06
                  ]
                }
              }
            }
          ]
          name "left_hip_yaw"
          boundingObject DEF left_hip_yaw_collision Mesh {
            url "left_hip_yaw_collision.stl"
          }
          physics Physics {
            density -1
            mass 0.059402
            centerOfMass [ -0.002183 -0.008948 -0.024756 ]
            inertiaMatrix [
              1.186270e-04 5.241240e-05 1.036410e-04
              -4.669810e-07 -1.503880e-06 1.014140e-07
            ]
          }
        }
      }
      HingeJoint {
        jointParameters HingeJointParameters {
                    dampingConstant IS MX106-damping
                    staticFriction IS MX106-friction
          axis 0.000000 0.000000 1.000000
          anchor -0.000000 -0.055000 -0.000000
        }
        device [
          RotationalMotor {
            name "right_hip_yaw"
            maxVelocity IS MX106-vel
            minPosition -3.14159
            maxPosition 3.14159
            maxTorque IS MX106-torque
          }
          PositionSensor {
                 resolution IS DYNAMIXEL-RESOLUTION
            name "right_hip_yaw_sensor"
          }
        ]
        endPoint Solid {
          translation -0.000000 -0.055000 -0.000000
          children [
            Shape {
              appearance DEF right_hip_yaw_material PBRAppearance {
                baseColor 0.286275 0.286275 0.286275
                roughness 1.000000
                metalness 0
              }
              geometry DEF right_hip_yaw_visual Mesh {
                url "right_hip_yaw_visual.stl"
              }
            }
            HingeJoint {
              jointParameters HingeJointParameters {
                    dampingConstant IS MX106-damping
                    staticFriction IS MX106-friction
                axis 1.000000 -0.000000 -0.000004
                anchor 0.022133 0.000000 -0.054500
              }
              device [
                RotationalMotor {
                  name "right_hip_roll"
                  maxVelocity IS MX106-vel
                  minPosition -3.14159
                  maxPosition 3.14159
                  maxTorque IS MX106-torque
                }
                PositionSensor {
                 resolution IS DYNAMIXEL-RESOLUTION
                  name "right_hip_roll_sensor"
                }
              ]
              endPoint Solid {
                translation 0.022133 0.000000 -0.054500
                rotation 0.000000 1.000000 -0.000000 1.570800
                children [
                  Shape {
                    appearance DEF right_hip_roll_material PBRAppearance {
                      baseColor 0.286275 0.286275 0.286275
                      roughness 1.000000
                      metalness 0
                    }
                    geometry DEF right_hip_roll_visual Mesh {
                      url "right_hip_roll_visual.stl"
                    }
                  }
                  HingeJoint {
                    jointParameters HingeJointParameters {
                    dampingConstant IS MX106-damping
                    staticFriction IS MX106-friction
                      axis 0.000000 1.000000 -0.000004
                      anchor -0.000000 0.000000 0.000000
                    }
                    device [
                      RotationalMotor {
                        name "right_hip_pitch"
                        maxVelocity IS MX106-vel
                        minPosition -3.14159
                        maxPosition 3.14159
                        maxTorque IS MX106-torque
                      }
                      PositionSensor {
                 resolution IS DYNAMIXEL-RESOLUTION
                        name "right_hip_pitch_sensor"
                      }
                    ]
                    endPoint Solid {
                      translation -0.000000 0.000000 0.000000
                      rotation -1.000000 -0.000000 -0.000000 1.570800
                      children [
                        Shape {
                          appearance DEF right_upper_leg_material PBRAppearance {
                            baseColor 0.701961 0.701961 0.701961
                            roughness 1.000000
                            metalness 0
                          }
                          geometry DEF right_upper_leg_visual Mesh {
                            url "right_upper_leg_visual.stl"
                          }
                        }
                        HingeJoint {
                          jointParameters HingeJointParameters {
                    dampingConstant IS MX106-damping
                    staticFriction IS MX106-friction
                            axis 0.000000 0.000000 1.000000
                            anchor 0.206046 0.056950 -0.000000
                          }
                          device [
                            RotationalMotor {
                              name "right_knee"
                              maxVelocity IS MX106-vel
                              minPosition -3.14159
                              maxPosition 3.14159
                              maxTorque IS MX106-torque
                            }
                            PositionSensor {
                 resolution IS DYNAMIXEL-RESOLUTION
                              name "right_knee_sensor"
                            }
                          ]
                          endPoint Solid {
                            translation 0.206046 0.056950 -0.000000
                            children [
                              Shape {
                                appearance DEF right_lower_leg_material PBRAppearance {
                                  baseColor 0.737255 0.721569 0.717647
                                  roughness 1.000000
                                  metalness 0
                                }
                                geometry DEF right_lower_leg_visual Mesh {
                                  url "right_lower_leg_visual.stl"
                                }
                              }
                              HingeJoint {
                                jointParameters HingeJointParameters {
                    dampingConstant IS MX106-damping
                    staticFriction IS MX106-friction
                                  axis 0.000000 0.000000 1.000000
                                  anchor 0.200203 0.000000 -0.000000
                                }
                                device [
                                  RotationalMotor {
                                    name "right_ankle_pitch"
                                    maxVelocity IS MX106-vel
                                    maxTorque IS MX106-torque
                                  }
                                  PositionSensor {
                 resolution IS DYNAMIXEL-RESOLUTION
                                    name "right_ankle_pitch_sensor"
                                  }
                                ]
                                endPoint Solid {
                                  translation 0.200203 0.000000 -0.000000
                                  children [
                                    Shape {
                                      appearance DEF right_ankle_material PBRAppearance {
                                        baseColor 0.286275 0.286275 0.286275
                                        roughness 1.000000
                                        metalness 0
                                      }
                                      geometry DEF right_ankle_visual Mesh {
                                        url "right_ankle_visual.stl"
                                      }
                                    }
                                    HingeJoint {
                                      jointParameters HingeJointParameters {
                    dampingConstant IS MX106-damping
                    staticFriction IS MX106-friction
                                        axis 0.000000 -1.000000 -0.000004
                                        anchor 0.000000 0.000000 -0.000000
                                      }
                                      device [
                                        RotationalMotor {
                                          name "right_ankle_roll"
                                          maxVelocity IS MX106-vel
                                          minPosition -3.14159
                                          maxPosition 3.14159
                                          maxTorque IS MX106-torque
                                        }
                                        PositionSensor {
                 resolution IS DYNAMIXEL-RESOLUTION
                                          name "right_ankle_roll_sensor"
                                        }
                                      ]
                                      endPoint Solid {
                                        translation 0.000000 0.000000 -0.000000
                                        rotation 1.000000 0.000000 0.000000 1.570800
                                        children [
                                          Shape {
                                            appearance DEF right_foot_material PBRAppearance {
                                              baseColor 0.286275 0.286275 0.286275
                                              roughness 1.000000
                                              metalness 0
                                            }
                                            geometry DEF right_foot_visual Mesh {
                                              url "right_foot_visual.stl"
                                            }
                                          }
                                          Solid {
                                            translation 0.036025 -0.000000 0.000000
                                            rotation -0.000000 -1.000000 -0.000000 1.570800
                                            children [
                                              Shape {
                                                appearance DEF right_foot_base_material PBRAppearance {
                                                  baseColor 0.500000 0.500000 0.500000
                                                  roughness 1.000000
                                                  metalness 0
                                                }
                                                geometry DEF right_foot_base_visual Mesh {
                                                  url "right_foot_base_visual.stl"
                                                }
                                              }
                                            ]
                                            name "right_foot_base"
                                            boundingObject DEF right_foot_base_collision Mesh {
                                              url "right_foot_base_collision.stl"
                                            }
                                            physics Physics {
                                              density -1
                                              mass 0.000000
                                            }
                                          }
                                        
                                          # Define four touch sensors for the right foot
                                          # Back right touch sensor on right foot
                                          TouchSensor {
                                            translation -0.041 0.025 -0.061
                                            name "right_touch_sensor_br"
                                            type "bumper"
                                          }
                                          # Back right touch sensor on right foot
                                          TouchSensor {
                                            translation 0.057 0.025 -0.061
                                            name "right_touch_sensor_bl"
                                            type "bumper"
                                          }
                                          # Front right touch sensor on right foot
                                          TouchSensor {
                                            translation 0.057 -0.154 -0.061
                                            name "right_touch_sensor_fl"
                                            type "bumper"
                                          }
                                          # Front right touch sensor on right foot
                                          TouchSensor {
                                            translation -0.041 -0.154 -0.061
                                            name "right_touch_sensor_fr"
                                            type "bumper"
                                          }
                                        ]
                                        name "right_foot [foot]"
                                        boundingObject DEF right_foot_collision Mesh {
                                          url "right_foot_collision.stl"
                                        }
                                        physics Physics {
                                          density -1
                                          mass 0.245567
                                          centerOfMass [ 0.024823 -0.007987 0.033281 ]
                                          inertiaMatrix [
                                            1.347120e-03 1.083760e-03 3.319970e-04
                                            9.735890e-06 2.226560e-08 1.340390e-05
                                          ]
                                        }
                                      }
                                    }
                                  ]
                                  name "right_ankle"
                                  boundingObject DEF right_ankle_collision Mesh {
                                    url "right_ankle_collision.stl"
                                  }
                                  physics Physics {
                                    density -1
                                    mass 0.329993
                                    centerOfMass [ -0.015733 0.021823 0.000509 ]
                                    inertiaMatrix [
                                      2.636480e-04 1.578480e-04 2.635610e-04
                                      7.537150e-09 2.473340e-19 3.690710e-06
                                    ]
                                  }
                                }
                              }
                            ]
                            name "right_lower_leg"
                            boundingObject DEF right_lower_leg_collision Mesh {
                              url "right_lower_leg_collision.stl"
                            }
                            physics Physics {
                              density -1
                              mass 0.089301
                              centerOfMass [ 0.100103 0.003882 0.000000 ]
                              inertiaMatrix [
                                9.012540e-05 4.089510e-04 3.363000e-04
                                -1.571840e-09 -7.871580e-11 -1.161010e-11
                              ]
                            }
                          }
                        }
                      ]
                      name "right_upper_leg"
                      boundingObject DEF right_upper_leg_collision Mesh {
                        url "right_upper_leg_collision.stl"
                      }
                      physics Physics {
                        density -1
                        mass 0.136613
                        centerOfMass [ 0.079792 0.033712 -0.000001 ]
                        inertiaMatrix [
                          1.457710e-04 5.852650e-04 5.100870e-04
                          -4.011750e-05 1.280150e-08 -8.070340e-10
                        ]
                      }
                    }
                  }
                ]
                name "right_hip_roll"
                boundingObject DEF right_hip_roll_collision Mesh {
                  url "right_hip_roll_collision.stl"
                }
                physics Physics {
                  density -1
                  mass 0.395953
                  centerOfMass [ 0.015733 -0.000232 -0.021829 ]
                  inertiaMatrix [
                    3.163670e-04 3.780250e-04 1.276370e-04
                    -9.045610e-09 -5.971580e-20 1.977870e-06
                  ]
                }
              }
            }
          ]
          name "right_hip_yaw"
          boundingObject DEF right_hip_yaw_collision Mesh {
            url "right_hip_yaw_collision.stl"
          }
          physics Physics {
            density -1
            mass 0.059402
            centerOfMass [ -0.002183 0.008948 -0.024756 ]
            inertiaMatrix [
              1.186260e-04 5.241170e-05 1.036410e-04
              4.671630e-07 -1.504170e-06 -1.010730e-07
            ]
          }
        }
      }
      HingeJoint {
        jointParameters HingeJointParameters {
                    dampingConstant IS MX106-damping
                    staticFriction IS MX106-friction
          axis -0.000000 -0.000000 1.000000
          anchor -0.008000 0.000000 0.208250
        }
        device [
          RotationalMotor {
            name "neck_yaw"
            maxVelocity IS MX106-vel
            minPosition -3.14159
            maxPosition 3.14159
            maxTorque IS MX106-torque
          }
          PositionSensor {
                 resolution IS DYNAMIXEL-RESOLUTION
            name "neck_yaw_sensor"
          }
        ]
        endPoint Solid {
          translation -0.008000 0.000000 0.208250
          rotation 0.000000 0.000000 -1.000000 3.141590
          children [
            Shape {
              appearance DEF neck_material PBRAppearance {
                baseColor 0.500000 0.500000 0.500000
                roughness 1.000000
                metalness 0
              }
              geometry DEF neck_visual Mesh {
                url "neck_visual.stl"
              }
            }
            HingeJoint {
              jointParameters HingeJointParameters {
                    dampingConstant IS MX106-damping
                    staticFriction IS MX106-friction
                axis -0.000004 1.000000 0.000000
                anchor -0.000245 -0.000255 0.048100
              }
              device [
                RotationalMotor {
                  name "neck_pitch"
                  maxVelocity IS MX106-vel
                  minPosition -3.14159
                  maxPosition 3.14159
                  maxTorque IS MX106-torque
                }
                PositionSensor {
                 resolution IS DYNAMIXEL-RESOLUTION
                  name "neck_pitch_sensor"
                }
              ]
              endPoint Solid {
                translation -0.000245 -0.000255 0.048100
                rotation -0.577350 0.577350 0.577352 2.094399
                children [
                  Shape {
                    appearance DEF head_material PBRAppearance {
                      baseColor 0.281665 0.281665 0.281665
                      roughness 1.000000
                      metalness 0
                    }
                    geometry DEF head_visual Mesh {
                      url "head_visual.stl"
                    }
                  }
                  Solid {
                    translation -0.064880 0.069952 -0.033795
                    rotation -0.590785 -0.570515 0.570513 2.074363
                    children [
                      Shape {
                        appearance DEF left_camera_material PBRAppearance {
                          baseColor 0.500000 0.500000 0.500000
                          roughness 1.000000
                          metalness 0
                        }
                        geometry DEF left_camera_visual Mesh {
                          url "left_camera_visual.stl"
                        }
                      }
                    
                      DEF left_camera Camera {
                        name "left_camera"
                        translation 0.0 0.0 0.0
                        rotation 0.0 0.0 1.0 0.0
                        # Set parameters from fields
                        fieldOfView IS fieldOfView
                        width IS cameraWidth
                        height IS cameraHeight
                        noise IS cameraNoise
                        motionBlur IS cameraMotionBlur
                        # We are using a rectilinear lens because there is no true spherical lens
                        spherical FALSE
                        # Allows the robot to detect objects in the world
                        recognition DEF recognition Recognition {
                          frameThickness 0       # Remove bounding boxes
                          segmentation TRUE      # Add segmentation
                        }
                      }
                    ]
                    name "left_camera"
                    boundingObject DEF left_camera_collision Mesh {
                      url "left_camera_collision.stl"
                    }
                    physics Physics {
                      density -1
                      mass 0.000000
                    }
                  }
                  Solid {
                    translation -0.064880 0.069952 0.034205
                    rotation -0.590785 -0.570515 0.570513 2.074363
                    children [
                      Shape {
                        appearance DEF right_camera_material PBRAppearance {
                          baseColor 0.500000 0.500000 0.500000
                          roughness 1.000000
                          metalness 0
                        }
                        geometry DEF right_camera_visual Mesh {
                          url "right_camera_visual.stl"
                        }
                      }
                    
                      DEF right_camera Camera {
                        name "right_camera"
                        translation 0.0 0.0 0.0
                        rotation 0.0 0.0 1.0 0.0
                        # Set parameters from fields
                        fieldOfView IS fieldOfView
                        width IS cameraWidth
                        height IS cameraHeight
                        noise IS cameraNoise
                        motionBlur IS cameraMotionBlur
                        # We are using a rectilinear lens because there is no true spherical lens
                        spherical FALSE
                        # Set the recognition parameters from the left camera
                        recognition USE recognition
                      }
                    ]
                    name "right_camera"
                    boundingObject DEF right_camera_collision Mesh {
                      url "right_camera_collision.stl"
                    }
                    physics Physics {
                      density -1
                      mass 0.000000
                    }
                  }
                ]
                name "head"
                boundingObject DEF head_collision Mesh {
                  url "head_collision.stl"
                }
                physics Physics {
                  density -1
                  mass 0.473503
                  centerOfMass [ -0.066556 0.010322 0.000101 ]
                  inertiaMatrix [
                    1.968500e-03 1.453310e-03 1.074450e-03
                    -6.700550e-06 7.819480e-06 -5.394190e-07
                  ]
                }
              }
            }
          ]
          name "neck"
          boundingObject DEF neck_collision Mesh {
            url "neck_collision.stl"
          }
          physics Physics {
            density -1
            mass 0.000000
          }
        }
      }
      HingeJoint {
        jointParameters HingeJointParameters {
                    dampingConstant IS MX106-damping
                    staticFriction IS MX106-friction
          axis -0.000004 -1.000000 0.000000
          anchor -0.000000 0.077000 0.177250
        }
        device [
          RotationalMotor {
            name "left_shoulder_pitch"
            maxVelocity IS MX106-vel
            minPosition -3.14159
            maxPosition 3.14159
            maxTorque IS MX106-torque
          }
          PositionSensor {
                 resolution IS DYNAMIXEL-RESOLUTION
            name "left_shoulder_pitch_sensor"
          }
        ]
        endPoint Solid {
          translation -0.000000 0.077000 0.177250
          rotation 0.577350 0.577350 -0.577352 2.094399
          children [
            Shape {
              appearance DEF left_shoulder_material PBRAppearance {
                baseColor 0.286275 0.286275 0.286275
                roughness 1.000000
                metalness 0
              }
              geometry DEF left_shoulder_visual Mesh {
                url "left_shoulder_visual.stl"
              }
            }
            HingeJoint {
              jointParameters HingeJointParameters {
                    dampingConstant IS MX106-damping
                    staticFriction IS MX106-friction
                axis -1.000000 -0.000004 -0.000004
                anchor 0.000000 0.010001 -0.047912
              }
              device [
                RotationalMotor {
                  name "left_shoulder_roll"
                  maxVelocity IS MX106-vel
                  minPosition -3.14159
                  maxPosition 3.14159
                  maxTorque IS MX106-torque
                }
                PositionSensor {
                 resolution IS DYNAMIXEL-RESOLUTION
                  name "left_shoulder_roll_sensor"
                }
              ]
              endPoint Solid {
                translation 0.000000 0.010001 -0.047912
                rotation -0.577350 -0.577352 0.577350 2.094399
                children [
                  Shape {
                    appearance DEF left_upper_arm_material PBRAppearance {
                      baseColor 0.286275 0.286275 0.286275
                      roughness 1.000000
                      metalness 0
                    }
                    geometry DEF left_upper_arm_visual Mesh {
                      url "left_upper_arm_visual.stl"
                    }
                  }
                  HingeJoint {
                    jointParameters HingeJointParameters {
                    dampingConstant IS MX106-damping
                    staticFriction IS MX106-friction
                      axis -0.000004 -1.000000 0.000000
                      anchor 0.157500 -0.000056 0.026950
                    }
                    device [
                      RotationalMotor {
                        name "left_elbow_pitch"
                        maxVelocity IS MX106-vel
                        minPosition -3.14159
                        maxPosition 3.14159
                        maxTorque IS MX106-torque
                      }
                      PositionSensor {
                 resolution IS DYNAMIXEL-RESOLUTION
                        name "left_elbow_pitch_sensor"
                      }
                    ]
                    endPoint Solid {
                      translation 0.157500 -0.000056 0.026950
                      rotation 0.577350 0.577350 -0.577352 2.094399
                      children [
                        Shape {
                          appearance DEF left_lower_arm_material PBRAppearance {
                            baseColor 0.286275 0.286275 0.286275
                            roughness 1.000000
                            metalness 0
                          }
                          geometry DEF left_lower_arm_visual Mesh {
                            url "left_lower_arm_visual.stl"
                          }
                        }
                      ]
                      name "left_lower_arm"
                      boundingObject DEF left_lower_arm_collision Mesh {
                        url "left_lower_arm_collision.stl"
                      }
                      physics Physics {
                        density -1
                        mass 0.287325
                        centerOfMass [ -0.000606 0.050997 -0.000069 ]
                        inertiaMatrix [
                          7.784710e-04 5.437270e-04 1.150600e-03
                          5.293450e-05 9.814920e-06 3.156180e-05
                        ]
                      }
                    }
                  }
                ]
                name "left_upper_arm"
                boundingObject DEF left_upper_arm_collision Mesh {
                  url "left_upper_arm_collision.stl"
                }
                physics Physics {
                  density -1
                  mass 0.134220
                  centerOfMass [ 0.083658 0.000830 -0.000118 ]
                  inertiaMatrix [
                    5.878330e-04 1.736360e-04 5.816010e-04
                    3.049430e-05 -3.416970e-05 6.348450e-06
                  ]
                }
              }
            }
          ]
          name "left_shoulder"
          boundingObject DEF left_shoulder_collision Mesh {
            url "left_shoulder_collision.stl"
          }
          physics Physics {
            density -1
            mass 0.084550
            centerOfMass [ -0.000036 0.002549 -0.028743 ]
            inertiaMatrix [
              7.302950e-05 9.743110e-05 9.336130e-05
              1.041460e-07 7.551920e-08 3.991160e-06
            ]
          }
        }
      }
      HingeJoint {
        jointParameters HingeJointParameters {
                    dampingConstant IS MX106-damping
                    staticFriction IS MX106-friction
          axis -0.000004 -1.000000 0.000000
          anchor -0.000000 -0.077000 0.177250
        }
        device [
          RotationalMotor {
            name "right_shoulder_pitch"
            maxVelocity IS MX106-vel
            minPosition -3.14159
            maxPosition 3.14159
            maxTorque IS MX106-torque
          }
          PositionSensor {
                 resolution IS DYNAMIXEL-RESOLUTION
            name "right_shoulder_pitch_sensor"
          }
        ]
        endPoint Solid {
          translation -0.000000 -0.077000 0.177250
          rotation 0.577350 0.577350 -0.577352 2.094399
          children [
            Shape {
              appearance DEF right_shoulder_material PBRAppearance {
                baseColor 0.286275 0.286275 0.286275
                roughness 1.000000
                metalness 0
              }
              geometry DEF right_shoulder_visual Mesh {
                url "right_shoulder_visual.stl"
              }
            }
            HingeJoint {
              jointParameters HingeJointParameters {
                    dampingConstant IS MX106-damping
                    staticFriction IS MX106-friction
                axis -1.000000 -0.000004 -0.000004
                anchor 0.000000 0.010001 0.047912
              }
              device [
                RotationalMotor {
                  name "right_shoulder_roll"
                  maxVelocity IS MX106-vel
                  minPosition -3.14159
                  maxPosition 3.14159
                  maxTorque IS MX106-torque
                }
                PositionSensor {
                 resolution IS DYNAMIXEL-RESOLUTION
                  name "right_shoulder_roll_sensor"
                }
              ]
              endPoint Solid {
                translation 0.000000 0.010001 0.047912
                rotation -0.577350 -0.577352 0.577350 2.094399
                children [
                  Shape {
                    appearance DEF right_upper_arm_material PBRAppearance {
                      baseColor 0.286275 0.286275 0.286275
                      roughness 1.000000
                      metalness 0
                    }
                    geometry DEF right_upper_arm_visual Mesh {
                      url "right_upper_arm_visual.stl"
                    }
                  }
                  HingeJoint {
                    jointParameters HingeJointParameters {
                    dampingConstant IS MX106-damping
                    staticFriction IS MX106-friction
                      axis -0.000004 -1.000000 0.000000
                      anchor 0.157500 0.000056 0.026950
                    }
                    device [
                      RotationalMotor {
                        name "right_elbow_pitch"
                        maxVelocity IS MX106-vel
                        minPosition -3.14159
                        maxPosition 3.14159
                        maxTorque IS MX106-torque
                      }
                      PositionSensor {
                 resolution IS DYNAMIXEL-RESOLUTION
                        name "right_elbow_pitch_sensor"
                      }
                    ]
                    endPoint Solid {
                      translation 0.157500 0.000056 0.026950
                      rotation 0.577350 0.577350 -0.577352 2.094399
                      children [
                        Shape {
                          appearance DEF right_lower_arm_material PBRAppearance {
                            baseColor 0.286275 0.286275 0.286275
                            roughness 1.000000
                            metalness 0
                          }
                          geometry DEF right_lower_arm_visual Mesh {
                            url "right_lower_arm_visual.stl"
                          }
                        }
                      ]
                      name "right_lower_arm"
                      boundingObject DEF right_lower_arm_collision Mesh {
                        url "right_lower_arm_collision.stl"
                      }
                      physics Physics {
                        density -1
                        mass 0.287350
                        centerOfMass [ -0.000605 0.051000 0.000069 ]
                        inertiaMatrix [
                          7.786250e-04 5.438180e-04 1.150820e-03
                          -3.067350e-05 1.106400e-05 -3.153360e-05
                        ]
                      }
                    }
                  }
                ]
                name "right_upper_arm"
                boundingObject DEF right_upper_arm_collision Mesh {
                  url "right_upper_arm_collision.stl"
                }
                physics Physics {
                  density -1
                  mass 0.134208
                  centerOfMass [ 0.083654 -0.000828 0.000126 ]
                  inertiaMatrix [
                    5.877890e-04 1.735990e-04 5.815650e-04
                    2.728700e-05 -3.204810e-05 -6.384350e-06
                  ]
                }
              }
            }
          ]
          name "right_shoulder"
          boundingObject DEF right_shoulder_collision Mesh {
            url "right_shoulder_collision.stl"
          }
          physics Physics {
            density -1
            mass 0.084550
            centerOfMass [ -0.000035 0.002549 0.028743 ]
            inertiaMatrix [
              7.302960e-05 9.743120e-05 9.336150e-05
              1.046390e-07 -7.539300e-08 -3.991360e-06
            ]
          }
        }
      }
    ]
    name IS name
    boundingObject DEF torso_collision Mesh {
      url "torso_collision.stl"
    }
    physics Physics {
      density -1
      mass 1.832640
      centerOfMass [ -0.000971 -0.000076 0.089849 ]
      inertiaMatrix [
        1.549240e-02 1.315490e-02 5.926760e-03
        9.191360e-05 -1.170230e-03 2.212050e-06
      ]
    }
  }
}
