#VRML_SIM R2021a utf8
# license: Apache License 2.0
# license url: http://www.apache.org/licenses/LICENSE-2.0
# This is a proto file for Webots for the NUgus
# Extracted from: NUgus.urdf

PROTO NUgus [
  field  SFVec3f     translation     0 0 0
  field  SFRotation  rotation        1 0 0 0                         # Make up be the positive Z axis
  field  MFString    robotTexture    "./robot/NUgus_textures/NUgus_base_color.jpg"
  field  SFString    name            "NUgus"                         # Is `Robot.name`.
  field  SFString    controller      "void"                          # Is `Robot.controller`.
  field  MFString    controllerArgs  []                              # Is `Robot.controllerArgs`.
  field  SFString    customData      ""                              # Is `Robot.customData`.
  field  SFBool      supervisor      FALSE                           # Is `Robot.supervisor`.
  field  SFBool      synchronization TRUE                            # Is `Robot.synchronization`.
  field  SFBool      selfCollision   FALSE                           # Is `Robot.selfCollision`.
  field  MFColor     recognitionColors [0 0 1]
  field SFFloat      fieldOfView          1.5707
  field SFInt32      cameraWidth          640
  field SFInt32      cameraHeight         480
  field SFFloat      cameraLensFocalLength 1.98
  field SFFloat      cameraNoise          0.000000001
  field SFFloat      cameraMotionBlur     10
  field  SFFloat     DYNAMIXEL-RESOLUTION 0.0015        # Resolution of the encoder for DYNAMIXEL servo (See section 2.0.3 of docs/Robot_Model_RoboCup_2021)
]
{
  Robot {
    translation IS translation
    rotation IS rotation
    controller IS controller
    controllerArgs IS controllerArgs
    customData IS customData
    supervisor IS supervisor
    synchronization IS synchronization
    selfCollision IS selfCollision

    children [
      %{
        if fields.name.value ~= '' then
          -- name is supposed to be something like "red player 2" or "blue player 1"
          local words = {}
          for word in fields.name.value:gmatch("%w+") do table.insert(words, word) end
          local color = words[1]
          local number = words[3]
      }%
      DEF jerseyFront JerseyFront {
        jerseyFrontTexture [
          %{='"./robot/textures/NUgus_front_' .. color .. '_' .. number .. '.jpg"'}%
        ]
      }
      DEF jerseyBack JerseyBack {
        jerseyBackTexture [
          %{='"./robot/textures/NUgus_back_' .. color .. '_' .. number .. '.jpg"'}%
        ]
      }

      Transform {
        translation 0.000000 0.000000 0.000000
        rotation 0.000000 0.000000 1.000000 1.570790
        children [
          DEF JERSEY_FRONT_SLOT Slot {
            type "jersey front"
            endPoint IS jerseyFront
          }
          DEF JERSEY_BACK_SLOT Slot {
            type "jersey back"
            endPoint IS jerseyBack
          }
          DEF torso NUgus_torsoMesh {
            robotTexture IS robotTexture
          }
        ]
      }
      HingeJoint {
        jointParameters HingeJointParameters {
          axis 0.000006 1.000000 -0.000000
          anchor 0.005000 -0.115000 0.180000
          dampingConstant 0.0
          staticFriction 0.0
        }
        device [
          RotationalMotor {
            name "right_shoulder_pitch [shoulder]"
            maxVelocity 8.16814
            minPosition -3.14159265359
            maxPosition 3.14159265359
            maxTorque 7.3
          }
          PositionSensor {
            name "right_shoulder_pitch_sensor"
            resolution IS DYNAMIXEL-RESOLUTION
          }
        ]
        endPoint Solid {
          translation 0.005000 -0.115000 0.180000
          rotation -0.577351 -0.577348 0.577351 2.094388
          children [
            DEF right_shoulder NUgus_right_shoulderMesh {
              robotTexture IS robotTexture
            }
            HingeJoint {
              jointParameters HingeJointParameters {
                axis 0.000000 -1.000000 0.000006
                anchor -0.015000 0.000000 0.005000
                dampingConstant 0.0
                staticFriction 0.0
              }
              device [
                RotationalMotor {
                  name "right_shoulder_roll"
                  maxVelocity 8.16814
                  minPosition -3.14159265359
                  maxPosition 3.14159265359
                  maxTorque 7.3
                }
                PositionSensor {
                  name "right_shoulder_roll_sensor"
                  resolution IS DYNAMIXEL-RESOLUTION
                }
              ]
              endPoint Solid {
                translation -0.015000 0.000000 0.005000
                rotation 1.000000 0.000000 0.000000 1.570790
                children [
                  DEF right_upper_arm NUgus_right_upper_armMesh {
                    robotTexture [
                      %{='"./robot/textures/NUgus_upper_arm_' .. color .. '.jpg"'}%
                    ]
                  }
                  HingeJoint {
                    jointParameters HingeJointParameters {
                      axis 1.000000 0.000000 0.000000
                      anchor 0.010000 -0.190000 0.040000
                      dampingConstant 0.0
                      staticFriction 0.0
                    }
                    device [
                      RotationalMotor {
                        name "right_elbow_pitch"
                        maxVelocity 8.16814
                        minPosition -3.14159265359
                        maxPosition 3.14159265359
                        maxTorque 7.3
                      }
                      PositionSensor {
                        name "right_elbow_pitch_sensor"
                        resolution IS DYNAMIXEL-RESOLUTION
                      }
                    ]
                    endPoint Solid {
                      translation 0.010000 -0.190000 0.040000
                      rotation 0.000000 1.000000 0.000000 0.000000
                      children [
                        DEF right_lower_arm NUgus_right_lower_armMesh {
                          robotTexture [
                            %{='"./robot/textures/NUgus_lower_arm_' .. color .. '.jpg"'}%
                          ]
                        }
                      ]
                      name "right_lower_arm [arm]"
                      boundingObject USE right_lower_arm
                      physics Physics {
                        density -1
                        mass 0.260000
                        centerOfMass [ 0.053360 -0.000810 0.000600 ]
                        inertiaMatrix [
                          3.407159e-04 1.769213e-03 1.618059e-03
                          1.182367e-04 -2.883079e-05 4.685687e-06
                        ]
                      }
                    }
                  }
                ]
                name "right_upper_arm [arm]"
                boundingObject USE right_upper_arm
                physics Physics {
                  density -1
                  mass 0.297000
                  centerOfMass [ -0.000470 -0.000480 -0.047850 ]
                  inertiaMatrix [
                    2.440903e-03 2.283834e-03 5.366937e-04
                    -3.671369e-06 -1.389145e-04 -1.979533e-05
                  ]
                }
              }
            }
          ]
          name "right_shoulder [arm]"
          boundingObject USE right_shoulder
          physics Physics {
            density -1
            mass 0.025434
            centerOfMass [ 0.003490 -0.001680 0.003750 ]
            inertiaMatrix [
              6.360000e-04 4.850000e-04 6.280000e-04
              2.000000e-06 -3.500000e-05 6.000000e-06
            ]
          }
        }
      }
      HingeJoint {
        jointParameters HingeJointParameters {
          axis 0.000006 1.000000 -0.000000
          anchor 0.005000 0.115000 0.180000
          dampingConstant 0.0
          staticFriction 0.0
        }
        device [
          RotationalMotor {
            name "left_shoulder_pitch [shoulder]"
            maxVelocity 8.16814
            minPosition -3.14159265359
            maxPosition 3.14159265359
            maxTorque 7.3
          }
          PositionSensor {
            name "left_shoulder_pitch_sensor"
            resolution IS DYNAMIXEL-RESOLUTION
          }
        ]
        endPoint Solid {
          translation 0.005000 0.115000 0.180000
          rotation -0.577351 -0.577348 0.577351 2.094388
          children [
            DEF left_shoulder NUgus_left_shoulderMesh {
              robotTexture IS robotTexture
            }
            HingeJoint {
              jointParameters HingeJointParameters {
                axis 0.000000 -1.000000 0.000006
                anchor 0.015000 0.000000 0.005000
                dampingConstant 0.0
                staticFriction 0.0
              }
              device [
                RotationalMotor {
                  name "left_shoulder_roll"
                  maxVelocity 8.16814
                  minPosition -3.14159265359
                  maxPosition 3.14159265359
                  maxTorque 7.3
                }
                PositionSensor {
                  name "left_shoulder_roll_sensor"
                  resolution IS DYNAMIXEL-RESOLUTION
                }
              ]
              endPoint Solid {
                translation 0.015000 0.000000 0.005000
                rotation 1.000000 0.000000 0.000000 1.570790
                children [
                  DEF left_upper_arm NUgus_left_upper_armMesh {
                    robotTexture [
                      %{='"./robot/textures/NUgus_upper_arm_' .. color .. '.jpg"'}%
                    ]
                  }
                  HingeJoint {
                    jointParameters HingeJointParameters {
                      axis 1.000000 0.000000 0.000000
                      anchor -0.010000 -0.190000 0.039990
                      dampingConstant 0.0
                      staticFriction 0.0
                    }
                    device [
                      RotationalMotor {
                        name "left_elbow_pitch"
                        maxVelocity 8.16814
                        minPosition -3.14159265359
                        maxPosition 3.14159265359
                        maxTorque 7.3
                      }
                      PositionSensor {
                        name "left_elbow_pitch_sensor"
                        resolution IS DYNAMIXEL-RESOLUTION
                      }
                    ]
                    endPoint Solid {
                      translation -0.010000 -0.190000 0.039990
                      rotation 0.000000 1.000000 0.000000 0.000000
                      children [
                        DEF left_lower_arm NUgus_left_lower_armMesh {
                          robotTexture [
                            %{='"./robot/textures/NUgus_lower_arm_' .. color .. '.jpg"'}%
                          ]
                        }
                      ]
                      name "left_lower_arm [arm]"
                      boundingObject USE left_lower_arm
                      physics Physics {
                        density -1
                        mass 0.260000
                        centerOfMass [ 0.053360 -0.000810 0.000600 ]
                        inertiaMatrix [
                          3.407159e-04 1.769213e-03 1.618059e-03
                          1.182367e-04 -2.883079e-05 4.685687e-06
                        ]
                      }
                    }
                  }
                ]
                name "left_upper_arm [arm]"
                boundingObject USE left_upper_arm
                physics Physics {
                  density -1
                  mass 0.297000
                  centerOfMass [ -0.000470 0.000480 -0.047850 ]
                  inertiaMatrix [
                    2.440903e-03 2.283834e-03 5.366937e-04
                    -3.671369e-06 -1.389145e-04 -1.979533e-05
                  ]
                }
              }
            }
          ]
          name "left_shoulder [arm]"
          boundingObject USE left_shoulder
          physics Physics {
            density -1
            mass 0.025434
            centerOfMass [ 0.003490 -0.001680 0.003750 ]
            inertiaMatrix [
              6.360000e-04 4.850000e-04 6.280000e-04
              -2.000000e-06 -3.500000e-05 -6.000000e-06
            ]
          }
        }
      }
      HingeJoint {
        jointParameters HingeJointParameters {
          axis 0.000000 0.000000 1.000000
          anchor 0.000000 -0.055000 0.000000
          dampingConstant 0.0
          staticFriction 0.0
        }
        device [
          RotationalMotor {
            name "right_hip_yaw"
            maxVelocity 5.75959
            minPosition -3.14159265359
            maxPosition 3.14159265359
            maxTorque 10.0
          }
          PositionSensor {
            name "right_hip_yaw_sensor"
            resolution IS DYNAMIXEL-RESOLUTION
          }
        ]
        endPoint Solid {
          translation 0.000000 -0.055000 0.000000
          rotation 0.000000 0.000000 1.000000 1.570790
          children [
            DEF right_hip_yaw NUgus_right_hip_yawMesh {
              robotTexture IS robotTexture
            }
            HingeJoint {
              jointParameters HingeJointParameters {
                axis 0.000000 -1.000000 0.000000
                anchor 0.000000 0.000000 -0.060000
                dampingConstant 0.0
                staticFriction 0.0
              }
              device [
                RotationalMotor {
                  name "right_hip_roll [hip]"
                  maxVelocity 5.75959
                  minPosition -3.14159265359
                  maxPosition 3.14159265359
                  maxTorque 10.0
                }
                PositionSensor {
                  name "right_hip_roll_sensor"
                  resolution IS DYNAMIXEL-RESOLUTION
                }
              ]
              endPoint Solid {
                translation 0.000000 0.000000 -0.060000
                rotation 0.000000 1.000000 0.000000 0.000000
                children [
                  DEF right_hip_roll NUgus_right_hip_rollMesh {
                    robotTexture IS robotTexture
                  }
                  HingeJoint {
                    jointParameters HingeJointParameters {
                      axis 1.000000 0.000000 0.000000
                      anchor 0.000000 -0.010000 0.010000
                      dampingConstant 0.0
                      staticFriction 0.0
                    }
                    device [
                      RotationalMotor {
                        name "right_hip_pitch"
                        maxVelocity 5.75959
                        minPosition -3.14159265359
                        maxPosition 3.14159265359
                        maxTorque 10.0
                      }
                      PositionSensor {
                        name "right_hip_pitch_sensor"
                        resolution IS DYNAMIXEL-RESOLUTION
                      }
                    ]
                    endPoint Solid {
                      translation 0.000000 -0.010000 0.010000
                      rotation -1.000000 0.000000 0.000000 0.050000
                      children [
                        DEF right_upper_leg NUgus_right_upper_legMesh {
                          robotTexture IS robotTexture
                        }
                        HingeJoint {
                          jointParameters HingeJointParameters {
                            axis 1.000000 0.000000 0.000000
                            anchor 0.000000 0.009990 -0.199750
                            dampingConstant 0.0
                            staticFriction 0.0
                          }
                          device [
                            RotationalMotor {
                              name "right_knee_pitch"
                              maxVelocity 5.75959
                              minPosition -3.14159265359
                              maxPosition 3.14159265359
                              maxTorque 10.0
                            }
                            PositionSensor {
                              name "right_knee_pitch_sensor"
                              resolution IS DYNAMIXEL-RESOLUTION
                            }
                          ]
                          endPoint Solid {
                            translation 0.000000 0.009990 -0.199750
                            rotation 1.000000 0.000000 0.000000 0.050000
                            children [
                              DEF right_lower_leg NUgus_right_lower_legMesh {
                                robotTexture [
                                  %{='"./robot/textures/NUgus_lower_leg_' .. color .. '.jpg"'}%
                                ]
                              }
                              HingeJoint {
                                jointParameters HingeJointParameters {
                                  axis 1.000000 0.000003 -0.000000
                                  anchor 0.000000 0.010000 -0.200000
                                  dampingConstant 0.0
                                  staticFriction 0.0
                                }
                                device [
                                  RotationalMotor {
                                    name "right_ankle_pitch"
                                    maxVelocity 5.75959
                                    minPosition -3.14159265359
                                    maxPosition 3.14159265359
                                    maxTorque 10.0
                                  }
                                  PositionSensor {
                                    name "right_ankle_pitch_sensor"
                                    resolution IS DYNAMIXEL-RESOLUTION
                                  }
                                ]
                                endPoint Solid {
                                  translation 0.000000 0.010000 -0.200000
                                  rotation 0.000001 -1.000000 -0.000001 3.141593
                                  children [
                                    DEF right_ankle NUgus_right_ankleMesh {
                                      robotTexture IS robotTexture
                                    }
                                    HingeJoint {
                                      jointParameters HingeJointParameters {
                                        axis 0.000003 -1.000000 0.000003
                                        anchor 0.000000 0.040000 0.000000
                                        dampingConstant 0.0
                                        staticFriction 0.0
                                      }
                                      device [
                                        RotationalMotor {
                                          name "right_ankle_roll"
                                          maxVelocity 5.75959
                                          minPosition -3.14159265359
                                          maxPosition 3.14159265359
                                          maxTorque 10.0
                                        }
                                        PositionSensor {
                                          name "right_ankle_roll_sensor"
                                          resolution IS DYNAMIXEL-RESOLUTION
                                        }
                                      ]
                                      endPoint Solid {
                                        translation 0.000000 0.040000 0.000000
                                        rotation -0.000001 1.000000 -0.000001 3.141593
                                        children [
                                          DEF right_foot NUgus_right_footMesh {
                                            robotTexture IS robotTexture
                                          }
                                        ]
                                        name "right_foot [foot]"
                                        boundingObject USE right_foot
                                        physics Physics {
                                          density -1
                                          mass 0.205000
                                          centerOfMass [ 0.030800 0.008770 0.011290 ]
                                          inertiaMatrix [
                                            4.692276e-04 1.083619e-03 1.390118e-03
                                            1.237290e-05 5.165617e-06 -1.759415e-06
                                          ]
                                        }
                                      }
                                    }
                                  ]
                                  name "right_ankle"
                                  boundingObject USE right_ankle
                                  physics Physics {
                                    density -1
                                    mass 0.306000
                                    centerOfMass [ -0.015730 0.000510 -0.021970 ]
                                    inertiaMatrix [
                                      1.179297e-04 2.167529e-04 2.619357e-04
                                      3.750778e-06 3.762394e-06 1.047191e-06
                                    ]
                                  }
                                }
                              }
                            ]
                            name "right_lower_leg"
                            boundingObject USE right_lower_leg
                            physics Physics {
                              density -1
                              mass 0.177000
                              centerOfMass [ -0.100000 0.001280 -0.007070 ]
                              inertiaMatrix [
                                2.629853e-04 1.587092e-03 1.417721e-03
                                -8.383225e-06 2.634340e-04 -6.909201e-07
                              ]
                            }
                          }
                        }
                      ]
                      name "right_upper_leg"
                      boundingObject USE right_upper_leg
                      physics Physics {
                        density -1
                        mass 0.387000
                        centerOfMass [ -0.086820 -0.000990 -0.003220 ]
                        inertiaMatrix [
                          6.967005e-04 2.392788e-03 2.056922e-03
                          -9.534768e-06 -4.706246e-04 1.168766e-07
                        ]
                      }
                    }
                  }
                ]
                name "right_hip_roll"
                boundingObject USE right_hip_roll
                physics Physics {
                  density -1
                  mass 0.306000
                  centerOfMass [ 0.015730 -0.000030 -0.020710 ]
                  inertiaMatrix [
                    1.179297e-04 2.167529e-04 2.619357e-04
                    3.750778e-06 -3.762394e-06 -1.047191e-06
                  ]
                }
              }
            }
          ]
          name "right_hip_yaw"
          boundingObject USE right_hip_yaw
          physics Physics {
            density -1
            mass 0.067000
            centerOfMass [ -0.002180 -0.046050 -0.024750 ]
            inertiaMatrix [
              8.822908e-04 1.744669e-03 1.996967e-03
              1.677450e-06 -7.823405e-06 -2.533161e-05
            ]
          }
        }
      }
      HingeJoint {
        jointParameters HingeJointParameters {
          axis 0.000000 0.000000 1.000000
          anchor 0.000000 0.055000 0.000000
          dampingConstant 0.0
          staticFriction 0.0
        }
        device [
          RotationalMotor {
            name "left_hip_yaw"
            maxVelocity 5.75959
            minPosition -3.14159265359
            maxPosition 3.14159265359
            maxTorque 10.0
          }
          PositionSensor {
            name "left_hip_yaw_sensor"
            resolution IS DYNAMIXEL-RESOLUTION
          }
        ]
        endPoint Solid {
          translation 0.000000 0.055000 0.000000
          rotation 0.000000 0.000000 1.000000 1.570790
          children [
            DEF left_hip_yaw NUgus_left_hip_yawMesh {
              robotTexture IS robotTexture
            }
            HingeJoint {
              jointParameters HingeJointParameters {
                axis 0.000000 -1.000000 0.000000
                anchor 0.000000 0.000000 -0.060000
                dampingConstant 0.0
                staticFriction 0.0
              }
              device [
                RotationalMotor {
                  name "left_hip_roll [hip]"
                  maxVelocity 5.75959
                  minPosition -3.14159265359
                  maxPosition 3.14159265359
                  maxTorque 10.0
                }
                PositionSensor {
                  name "left_hip_roll_sensor"
                  resolution IS DYNAMIXEL-RESOLUTION
                }
              ]
              endPoint Solid {
                translation 0.000000 0.000000 -0.060000
                rotation 0.000000 1.000000 0.000000 0.000000
                children [
                  DEF left_hip_roll NUgus_left_hip_rollMesh {
                    robotTexture IS robotTexture
                  }
                  HingeJoint {
                    jointParameters HingeJointParameters {
                      axis 1.000000 0.000000 0.000000
                      anchor 0.000000 -0.010000 0.000000
                      dampingConstant 0.0
                      staticFriction 0.0
                    }
                    device [
                      RotationalMotor {
                        name "left_hip_pitch"
                        maxVelocity 5.75959
                        minPosition -3.14159265359
                        maxPosition 3.14159265359
                        maxTorque 10.0
                      }
                      PositionSensor {
                        name "left_hip_pitch_sensor"
                        resolution IS DYNAMIXEL-RESOLUTION
                      }
                    ]
                    endPoint Solid {
                      translation 0.000000 -0.010000 0.000000
                      rotation -1.000000 0.000000 0.000000 0.050000
                      children [
                        DEF left_upper_leg NUgus_left_upper_legMesh {
                          robotTexture IS robotTexture
                        }
                        HingeJoint {
                          jointParameters HingeJointParameters {
                            axis 1.000000 0.000000 0.000000
                            anchor 0.000000 0.009490 -0.189760
                            dampingConstant 0.0
                            staticFriction 0.0
                          }
                          device [
                            RotationalMotor {
                              name "left_knee_pitch"
                              maxVelocity 5.75959
                              minPosition -3.14159265359
                              maxPosition 3.14159265359
                              maxTorque 10.0
                            }
                            PositionSensor {
                              name "left_knee_pitch_sensor"
                              resolution IS DYNAMIXEL-RESOLUTION
                            }
                          ]
                          endPoint Solid {
                            translation 0.000000 0.009490 -0.189760
                            rotation 1.000000 0.000000 0.000000 0.050000
                            children [
                              DEF left_lower_leg NUgus_left_lower_legMesh {
                                robotTexture [
                                  %{='"./robot/textures/NUgus_lower_leg_' .. color .. '.jpg"'}%
                                ]
                                %{ end }%
                              }
                              HingeJoint {
                                jointParameters HingeJointParameters {
                                  axis 1.000000 0.000003 -0.000000
                                  anchor 0.000000 0.010000 -0.200000
                                  dampingConstant 0.0
                                  staticFriction 0.0
                                }
                                device [
                                  RotationalMotor {
                                    name "left_ankle_pitch"
                                    maxVelocity 5.75959
                                    minPosition -3.14159265359
                                    maxPosition 3.14159265359
                                    maxTorque 10.0
                                  }
                                  PositionSensor {
                                    name "left_ankle_pitch_sensor"
                                    resolution IS DYNAMIXEL-RESOLUTION
                                  }
                                ]
                                endPoint Solid {
                                  translation 0.000000 0.010000 -0.200000
                                  rotation 0.000001 -1.000000 -0.000001 3.141593
                                  children [
                                    DEF left_ankle NUgus_left_ankleMesh {
                                      robotTexture IS robotTexture
                                    }
                                    HingeJoint {
                                      jointParameters HingeJointParameters {
                                        axis 0.000003 -1.000000 0.000003
                                        anchor 0.000000 0.040000 0.000000
                                        dampingConstant 0.0
                                        staticFriction 0.0
                                      }
                                      device [
                                        RotationalMotor {
                                          name "left_ankle_roll"
                                          maxVelocity 5.75959
                                          minPosition -3.14159265359
                                          maxPosition 3.14159265359
                                          maxTorque 10.0
                                        }
                                        PositionSensor {
                                          name "left_ankle_roll_sensor"
                                          resolution IS DYNAMIXEL-RESOLUTION
                                        }
                                      ]
                                      endPoint Solid {
                                        translation 0.000000 0.040000 0.000000
                                        rotation -0.000001 1.000000 -0.000001 3.141593
                                        children [
                                          DEF left_foot NUgus_left_footMesh {
                                            robotTexture IS robotTexture
                                          }
                                        ]
                                        name "left_foot [foot]"
                                        boundingObject USE left_foot
                                        physics Physics {
                                          density -1
                                          mass 0.205000
                                          centerOfMass [ 0.030800 0.008770 0.011290 ]
                                          inertiaMatrix [
                                            4.692276e-04 1.083619e-03 1.390118e-03
                                            -1.237290e-05 5.165617e-06 1.759415e-06
                                          ]
                                        }
                                      }
                                    }
                                  ]
                                  name "left_ankle"
                                  boundingObject USE left_ankle
                                  physics Physics {
                                    density -1
                                    mass 0.306000
                                    centerOfMass [ -0.015730 0.000510 -0.021970 ]
                                    inertiaMatrix [
                                      1.179297e-04 2.167529e-04 2.619357e-04
                                      -3.750778e-06 3.762394e-06 -1.047191e-06
                                    ]
                                  }
                                }
                              }
                            ]
                            name "left_lower_leg"
                            boundingObject USE left_lower_leg
                            physics Physics {
                              density -1
                              mass 0.177000
                              centerOfMass [ -0.100000 0.001280 -0.007070 ]
                              inertiaMatrix [
                                2.629853e-04 1.587092e-03 1.417721e-03
                                8.383225e-06 2.634340e-04 6.909201e-07
                              ]
                            }
                          }
                        }
                      ]
                      name "left_upper_leg"
                      boundingObject USE left_upper_leg
                      physics Physics {
                        density -1
                        mass 0.387000
                        centerOfMass [ -0.086820 -0.000990 -0.003220 ]
                        inertiaMatrix [
                          6.967005e-04 2.392788e-03 2.056922e-03
                          9.534768e-06 -4.706246e-04 -1.168766e-07
                        ]
                      }
                    }
                  }
                ]
                name "left_hip_roll"
                boundingObject USE left_hip_roll
                physics Physics {
                  density -1
                  mass 0.306000
                  centerOfMass [ 0.015730 0.000030 -0.020710 ]
                  inertiaMatrix [
                    1.179297e-04 2.167529e-04 2.619357e-04
                    3.750778e-06 -3.762394e-06 -1.047191e-06
                  ]
                }
              }
            }
          ]
          name "left_hip_yaw"
          boundingObject USE left_hip_yaw
          physics Physics {
            density -1
            mass 0.067000
            centerOfMass [ -0.002180 0.046050 -0.024750 ]
            inertiaMatrix [
              8.822261e-04 1.744628e-03 1.996990e-03
              -1.705523e-06 -7.854428e-06 2.533179e-05
            ]
          }
        }
      }
      DEF neck_yaw HingeJoint {
        jointParameters HingeJointParameters {
          axis 0.000000 0.000000 1.000000
          anchor 0.000000 0.000000 0.260000
          dampingConstant 0.0
          staticFriction 0.0
        }
        device [
          RotationalMotor {
            name "neck_yaw"
            maxVelocity 8.16814
            minPosition -3.14159265359
            maxPosition 3.14159265359
            maxTorque 7.3
          }
          PositionSensor {
            name "neck_yaw_sensor"
            resolution IS DYNAMIXEL-RESOLUTION
          }
        ]
        endPoint Solid {
          translation 0.000000 0.000000 0.260000
          rotation 0.000000 0.000000 1.000000 1.570790
          children [
            DEF neck NUgus_neckMesh {
              robotTexture IS robotTexture
            }
            DEF head_pitch HingeJoint {
              jointParameters HingeJointParameters {
                axis 1.000000 0.000000 0.000000
                anchor 0.000000 0.000000 0.000000
                dampingConstant 0.0
                staticFriction 0.0
              }
              device [
                RotationalMotor {
                  name "head_pitch"
                  maxVelocity 8.16814
                  minPosition -3.14159265359
                  maxPosition 3.14159265359
                  maxTorque 7.3
                }
                PositionSensor {
                  name "head_pitch_sensor"
                  resolution IS DYNAMIXEL-RESOLUTION
                }
              ]
              endPoint Solid {
                translation 0.000000 0.000000 0.000000
                rotation 0.000000 1.000000 0.000000 0.000000
                children [
                  DEF head NUgus_headMesh {
                    robotTexture IS robotTexture
                  }
                  Transform {
                    translation 0.000000 0.000000 0.000000
                    rotation 0.000000 0.000000 1.000000 -1.570790
                    children [
                      DEF right_camera Camera {
                        name "right_camera"
                        translation  0.0889361 -0.0352991  0.0713675
                        
                        fieldOfView IS fieldOfView
                        width IS cameraWidth
                        height IS cameraHeight
                        spherical FALSE
                        noise IS cameraNoise
                        motionBlur IS cameraMotionBlur

                        # Allows the robot to detect objects in the world
                        recognition DEF RECOGNITION Recognition {
                          frameThickness 0       # Remove bounding boxes
                          segmentation TRUE      # Add segmentation
                        }
                      }
                      DEF left_camera Camera {
                        name "left_camera"
                        translation 0.0889361 0.0352991 0.0713675
                        rotation  0.577322 -0.595552 -0.558585 2.06587

                        fieldOfView IS fieldOfView
                        width IS cameraWidth
                        height IS cameraHeight
                        spherical FALSE
                        noise IS cameraNoise
                        motionBlur IS cameraMotionBlur
                        
                        # Allows the robot to detect objects in the world
                        recognition DEF RECOGNITION Recognition {
                          frameThickness 0       # Remove bounding boxes
                          segmentation TRUE      # Add segmentation
                        }
                      }
                    ]
                  }
                ]
                name "head"
                boundingObject USE head
                physics Physics {
                  density -1
                  mass 0.419000
                  centerOfMass [ -0.054820 -0.000100 0.001170 ]
                  inertiaMatrix [
                    5.229543e-03 4.273822e-03 3.333632e-03
                    8.068689e-07 -7.854194e-05 2.263322e-07
                  ]
                }
              }
            }
          ]
          name "neck"
          boundingObject USE neck
          physics Physics {
            density -1
            mass 0.135000
            centerOfMass [ -0.006030 -0.001600 0.241150 ]
            inertiaMatrix [
              4.111124e-04 3.431749e-04 2.333899e-04
              1.344483e-10 -3.646935e-10 -1.246022e-05
            ]
          }
        }
      }
      Transform {
        # Accelerometer and Gyro are positioned 0.2m above torso base
        translation 0.000000 0.000000 0.2
        children [
          # lis331dlh Accelerometer (See Section 1. of docs/Robot_Model_RoboCup_2021 for details on parameters)
          # Axis: x forward, y left, z up
          Accelerometer {
            xAxis TRUE
            yAxis TRUE
            zAxis TRUE
            resolution 0.002
            lookupTable [
              -4.0625	0	0
              -4		0	0
              -3.9375	512	0.06976
              -3.875	1024	0.03488
              -3.8125	1536	0.023253333
              -3.75	  2048	0.01744
              -3.6875	2560	0.013952
              -3.625	3072	0.011626667
              -3.5625	3584	0.009965714
              -3.5	  4096	0.00872
              -3.4375	4608	0.007751111
              -3.375	5120	0.006976
              -3.3125	5632	0.006341818
              -3.25	  6144	0.005813333
              -3.1875	6656	0.005366154
              -3.125	7168	0.004982857
              -3.0625	7680	0.004650667
              -3		  8192	0.00436
              -2.9375	8704	0.004103529
              -2.875	9216	0.003875556
              -2.8125	9728	0.003671579
              -2.75	  10240	0.003488
              -2.6875	10752	0.003321905
              -2.625	11264	0.003170909
              -2.5625	11776	0.003033043
              -2.5	  12288	0.002906667
              -2.4375	12800	0.0027904
              -2.375	13312	0.002683077
              -2.3125	13824	0.002583704
              -2.25	  14336	0.002491429
              -2.1875	14848	0.002405517
              -2.125	15360	0.002325333
              -2.0625	15872	0.002250323
              -2		  16384	0.00218
              -1.9375	16896	0.002113939
              -1.875	17408	0.002051765
              -1.8125	17920	0.001993143
              -1.75	  18432	0.001937778
              -1.6875	18944	0.001885405
              -1.625	19456	0.001835789
              -1.5625	19968	0.001788718
              -1.5	  20480	0.001744
              -1.4375	20992	0.001701463
              -1.375	21504	0.001660952
              -1.3125	22016	0.001622326
              -1.25	  22528	0.001585455
              -1.1875	23040	0.001550222
              -1.125	23552	0.001516522
              -1.0625	24064	0.001484255
              -1		  24576	0.001453333
              -0.9375	25088	0.001423673
              -0.875	25600	0.0013952
              -0.8125	26112	0.001367843
              -0.75	  26624	0.001341538
              -0.6875	27136	0.001316226
              -0.625	27648	0.001291852
              -0.5625	28160	0.001268364
              -0.5	  28672	0.001245714
              -0.4375	29184	0.00122386
              -0.375	29696	0.001202759
              -0.3125	30208	0.001182373
              -0.25	  30720	0.001162667
              -0.1875	31232	0.001143607
              -0.125	31744	0.001125161
              -0.0625	32256	0.001107302
              0		    32768	0.00109
              0.0625	33280	0.001073231
              0.125	  33792	0.00105697
              0.1875	34304	0.001041194
              0.25	  34816	0.001025882
              0.3125	35328	0.001011014
              0.375	  35840	0.000996571
              0.4375	36352	0.000982535
              0.5		  36864	0.000968889
              0.5625	37376	0.000955616
              0.625	  37888	0.000942703
              0.6875	38400	0.000930133
              0.75	  38912	0.000917895
              0.8125	39424	0.000905974
              0.875	  39936	0.000894359
              0.9375	40448	0.000883038
              1		    40960	0.000872
              1.0625	41472	0.000861235
              1.125	  41984	0.000850732
              1.1875	42496	0.000840482
              1.25	  43008	0.000830476
              1.3125	43520	0.000820706
              1.375	  44032	0.000811163
              1.4375	44544	0.000801839
              1.5		  45056	0.000792727
              1.5625	45568	0.00078382
              1.625	  46080	0.000775111
              1.6875	46592	0.000766593
              1.75	  47104	0.000758261
              1.8125	47616	0.000750108
              1.875	  48128	0.000742128
              1.9375	48640	0.000734316
              2		    49152	0.000726667
              2.0625	49664	0.000719175
              2.125	  50176	0.000711837
              2.1875	50688	0.000704646
              2.25	  51200	0.0006976
              2.3125	51712	0.000690693
              2.375	  52224	0.000683922
              2.4375	52736	0.000677282
              2.5		  53248	0.000670769
              2.5625	53760	0.000664381
              2.625	  54272	0.000658113
              2.6875	54784	0.000651963
              2.75	  55296	0.000645926
              2.8125	55808	0.00064
              2.875	  56320	0.000634182
              2.9375	56832	0.000628468
              3		    57344	0.000622857
              3.0625	57856	0.000617345
              3.125	  58368	0.00061193
              3.1875	58880	0.000606609
              3.25	  59392	0.000601379
              3.3125	59904	0.000596239
              3.375	  60416	0.000591186
              3.4375	60928	0.000586218
              3.5		  61440	0.000581333
              3.5625	61952	0.000576529
              3.625	  62464	0.000571803
              3.6875	62976	0.000567154
              3.75	  63488	0.000562581
              3.8125	64000	0.00055808
              3.875	  64512	0.000553651
              3.9375	65024	0.000549291
              4		    65536	0
              4.0625	65536	0
            ]
          }
          # L3G4200D Gyro (See Section 1. of docs/Robot_Model_RoboCup_2021 for details on parameters)
          # Axis: x forward, y left, z up
          Gyro {
            xAxis TRUE
            yAxis TRUE
            zAxis TRUE
            resolution 0.0175
            lookupTable [
              -507.8125	0	0
              -500	0	0
              -492.1875	512	0.076804688
              -484.375	1024	0.038402344
              -476.5625	1536	0.025601563
              -468.75		2048	0.019201172
              -460.9375	2560	0.015360938
              -453.125	3072	0.012800781
              -445.3125	3584	0.010972098
              -437.5		4096	0.009600586
              -429.6875	4608	0.008533854
              -421.875	5120	0.007680469
              -414.0625	5632	0.006982244
              -406.25		6144	0.006400391
              -398.4375	6656	0.005908053
              -390.625	7168	0.005486049
              -382.8125	7680	0.005120313
              -375		  8192	0.004800293
              -367.1875	8704	0.004517923
              -359.375	9216	0.004266927
              -351.5625	9728	0.004042352
              -343.75		10240	0.003840234
              -335.9375	10752	0.003657366
              -328.125	11264	0.003491122
              -320.3125	11776	0.003339334
              -312.5		12288	0.003200195
              -304.6875	12800	0.003072188
              -296.875	13312	0.002954026
              -289.0625	13824	0.002844618
              -281.25		14336	0.002743025
              -273.4375	14848	0.002648438
              -265.625	15360	0.002560156
              -257.8125	15872	0.002477571
              -250		  16384	0.002400146
              -242.1875	16896	0.002327415
              -234.375	17408	0.002258961
              -226.5625	17920	0.00219442
              -218.75		18432	0.002133464
              -210.9375	18944	0.002075802
              -203.125	19456	0.002021176
              -195.3125	19968	0.001969351
              -187.5		20480	0.001920117
              -179.6875	20992	0.001873285
              -171.875	21504	0.001828683
              -164.0625	22016	0.001786156
              -156.25		22528	0.001745561
              -148.4375	23040	0.001706771
              -140.625	23552	0.001669667
              -132.8125	24064	0.001634142
              -125		  24576	0.001600098
              -117.1875	25088	0.001567443
              -109.375	25600	0.001536094
              -101.5625	26112	0.001505974
              -93.75		26624	0.001477013
              -85.9375	27136	0.001449145
              -78.125		27648	0.001422309
              -70.3125	28160	0.001396449
              -62.5		  28672	0.001371512
              -54.6875	29184	0.001347451
              -46.875		29696	0.001324219
              -39.0625	30208	0.001301774
              -31.25		30720	0.001280078
              -23.4375	31232	0.001259093
              -15.625		31744	0.001238785
              -7.8125		32256	0.001219122
              0			    32768	0.001200073
              7.8125		33280	0.001181611
              15.625		33792	0.001163707
              23.4375		34304	0.001146339
              31.25		  34816	0.001129481
              39.0625		35328	0.001113111
              46.875		35840	0.00109721
              54.6875		36352	0.001081756
              62.5		  36864	0.001066732
              70.3125		37376	0.001052119
              78.125		37888	0.001037901
              85.9375		38400	0.001024063
              93.75		  38912	0.001010588
              101.5625	39424	0.000997463
              109.375		39936	0.000984675
              117.1875	40448	0.000972211
              125			  40960	0.000960059
              132.8125	41472	0.000948206
              140.625		41984	0.000936643
              148.4375	42496	0.000925358
              156.25		43008	0.000914342
              164.0625	43520	0.000903585
              171.875		44032	0.000893078
              179.6875	44544	0.000882813
              187.5		  45056	0.000872781
              195.3125	45568	0.000862974
              203.125		46080	0.000853385
              210.9375	46592	0.000844008
              218.75		47104	0.000834834
              226.5625	47616	0.000825857
              234.375		48128	0.000817071
              242.1875	48640	0.00080847
              250			  49152	0.000800049
              257.8125	49664	0.000791801
              265.625		50176	0.000783721
              273.4375	50688	0.000775805
              281.25		51200	0.000768047
              289.0625	51712	0.000760442
              296.875		52224	0.000752987
              304.6875	52736	0.000745677
              312.5		  53248	0.000738507
              320.3125	53760	0.000731473
              328.125		54272	0.000724573
              335.9375	54784	0.000717801
              343.75		55296	0.000711155
              351.5625	55808	0.00070463
              359.375		56320	0.000698224
              367.1875	56832	0.000691934
              375			  57344	0.000685756
              382.8125	57856	0.000679688
              390.625		58368	0.000673725
              398.4375	58880	0.000667867
              406.25		59392	0.000662109
              414.0625	59904	0.00065645
              421.875		60416	0.000650887
              429.6875	60928	0.000645418
              437.5		  61440	0.000640039
              445.3125	61952	0.000634749
              453.125		62464	0.000629547
              460.9375	62976	0.000624428
              468.75		63488	0.000619393
              476.5625	64000	0.000614438
              484.375		64512	0.000609561
              492.1875	65024	0.000604761
              500			  65536	0
              507.8125	65536	0
            ]
          }
        ]
      }
    ]
    name IS name
    boundingObject Transform {
      translation 0.000000 0.000000 0.000000
      rotation 0.000000 0.000000 1.000000 1.570790
      children [
        USE torso
      ]
    }
    physics Physics {
      density -1
      mass 2.539000
      centerOfMass [ 0.005000 0.008880 0.102150 ]
      inertiaMatrix [
        1.665729e-02 4.225235e-03 5.550778e-02
        1.545186e-03 4.938658e-03 1.202753e-03
      ]
    }
  }
}
